<?xml version="1.0"?>
<robot name="kuka_iiwa14">

  <!-- ===== BASE LINK ===== -->
  <link name="base_link"/>

  <joint name="iiwa_base_joint" type="fixed">
    <parent link="base_link"/>
    <child link="iiwa_link_0"/>
    <origin xyz="0 0 0" rpy="0 0 0"/>
  </joint>

  <!-- ===== LINK 0 ===== -->
  <link name="iiwa_link_0">
    <visual>
      <origin xyz="0 0 0"/>
      <geometry>
        <mesh filename="../meshes/visual/link_0.obj"/>
      </geometry>
    </visual>
  </link>

  <!-- ===== JOINT 1 ===== -->
  <joint name="iiwa_joint_1" type="revolute">
    <parent link="iiwa_link_0"/>
    <child link="iiwa_link_1"/>
    <origin xyz="0 0 0.15185" rpy="0 0 0"/>
    <axis xyz="0 0 1"/>
    <limit lower="-6.28" upper="6.28" velocity="1.5" effort="150"/>
  </joint>

  <!-- ===== LINK 1 ===== -->
  <link name="iiwa_link_1">
    <visual>
      <geometry>
        <mesh filename="../meshes/visual/link_1.obj"/>
      </geometry>
    </visual>
  </link>

  <!-- ===== JOINT 2 ===== -->
  <joint name="iiwa_joint_2" type="revolute">
    <parent link="iiwa_link_1"/>
    <child link="iiwa_link_2"/>
    <origin xyz="0 0 0" rpy="1.5708 0 3.1416"/>
    <axis xyz="0 0 1"/>
    <limit lower="-6.28" upper="6.28" velocity="1.5" effort="150"/>
  </joint>

  <!-- ===== LINK 2 ===== -->
  <link name="iiwa_link_2">
    <visual>
      <geometry>
        <mesh filename="../meshes/visual/link_2.obj"/>
      </geometry>
    </visual>
  </link>

  <!-- ===== JOINT 3 ===== -->
  <joint name="iiwa_joint_3" type="revolute">
    <parent link="iiwa_link_2"/>
    <child link="iiwa_link_3"/>
    <origin xyz="0 0.24355 0.03" rpy="-3.1416 0 -3.1416"/>
    <axis xyz="0 0 1"/>
    <limit lower="-2.967" upper="2.967" velocity="1.5" effort="300"/>
  </joint>

  <!-- ===== LINK 3 ===== -->
  <link name="iiwa_link_3">
    <visual>
      <geometry>
        <mesh filename="../meshes/visual/link_3.obj"/>
      </geometry>
    </visual>
  </link>

  <!-- ===== JOINT 4 ===== -->
  <joint name="iiwa_joint_4" type="revolute">
    <parent link="iiwa_link_3"/>
    <child link="iiwa_link_4"/>
    <origin xyz="0 0.2132 0.045" rpy="0 0 0"/>
    <axis xyz="0 0 1"/>
    <limit lower="-6.28" upper="6.28" velocity="1.5" effort="150"/>
  </joint>

  <!-- ===== LINK 4 ===== -->
  <link name="iiwa_link_4">
    <visual>
      <geometry>
        <mesh filename="../meshes/visual/link_4.obj"/>
      </geometry>
    </visual>
  </link>

  <!-- ===== JOINT 5 ===== -->
  <joint name="iiwa_joint_5" type="revolute">
    <parent link="iiwa_link_4"/>
    <child link="iiwa_link_5"/>
    <origin xyz="0 0 -0.13105" rpy="-1.5708 3.1416 0"/>
    <axis xyz="0 0 1"/>
    <limit lower="-6.28" upper="6.28" velocity="1.5" effort="150"/>
  </joint>

  <!-- ===== LINK 5 ===== -->
  <link name="iiwa_link_5">
    <visual>
      <geometry>
        <mesh filename="../meshes/visual/link_5.obj"/>
      </geometry>
    </visual>
  </link>

  <!-- ===== JOINT 6 ===== -->
  <joint name="iiwa_joint_6" type="revolute">
    <parent link="iiwa_link_5"/>
    <child link="iiwa_link_6"/>
    <origin xyz="0 -0.089 0.103" rpy="1.5708 0 3.1416"/>
    <axis xyz="0 0 1"/>
    <limit lower="-6.28" upper="6.28" velocity="1.5" effort="150"/>
  </joint>

  <!-- ===== LINK 6 ===== -->
  <link name="iiwa_link_6">
    <visual>
      <geometry>
        <mesh filename="../meshes/visual/link_6.obj"/>
      </geometry>
    </visual>
  </link>

  <!-- ===== END EFFECTOR JOINT ===== -->
  <joint name="iiwa_joint_ee" type="fixed">
    <parent link="iiwa_link_6"/>
    <child link="iiwa_link_7"/>
    <origin xyz="0 0 0.12" rpy="0 0 0"/>
  </joint>

  <!-- ===== TIP LINK ===== -->
  <link name="iiwa_link_7">
    <visual>
      <geometry><sphere radius="0.04"/></geometry>
    </visual>
  </link>

</robot>
